<?xml version='1.0'?>
<sdf version='1.7'>
  <model name='golfinho'>
    <link name='base_link'>
      <inertial>
        <pose>9e-06 0 1e-05 0 -0 0</pose>
        <mass>320.004</mass>
        <inertia>
          <ixx>9.60649</ixx>
          <ixy>0</ixy>
          <ixz>-0.00173708</ixz>
          <iyy>74.3788</iyy>
          <iyz>0</iyz>
          <izz>83.9737</izz>
        </inertia>
      </inertial>
      <velocity_decay/>
      <velocity_decay/>
      <gravity>1</gravity>
      <sensor name='twr_imu' type='imu'>
        <always_on>1</always_on>
        <update_rate>100</update_rate>
        <visualize>1</visualize>
        <imu>
          <angular_velocity>
            <x>
              <noise type='gaussian'>
                <mean>0</mean>
                <stddev>0.0002</stddev>
              </noise>
            </x>
            <y>
              <noise type='gaussian'>
                <mean>0</mean>
                <stddev>0.0002</stddev>
              </noise>
            </y>
            <z>
              <noise type='gaussian'>
                <mean>0</mean>
                <stddev>0.0002</stddev>
              </noise>
            </z>
          </angular_velocity>
          <linear_acceleration>
            <x>
              <noise type='gaussian'>
                <mean>0</mean>
                <stddev>0.017</stddev>
              </noise>
            </x>
            <y>
              <noise type='gaussian'>
                <mean>0</mean>
                <stddev>0.017</stddev>
              </noise>
            </y>
            <z>
              <noise type='gaussian'>
                <mean>0</mean>
                <stddev>0.017</stddev>
              </noise>
            </z>
          </linear_acceleration>
          <orientation>
            <x>
              <noise type='gaussian'>
                <mean>0.0</mean>
                <stddev>2e-3</stddev>
              </noise>
            </x>
            <y>
              <noise type='gaussian'>
                <mean>0.0</mean>
                <stddev>2e-3</stddev>
              </noise>
            </y>
            <z>
              <noise type='gaussian'>
                <mean>0.0</mean>
                <stddev>2e-3</stddev>
              </noise>
            </z>
          </orientation>
        </imu>
        <plugin name='two_wheeled_robot_imu' filename='libgazebo_ros_imu_sensor.so'>
          <initial_orientation_as_reference>0</initial_orientation_as_reference>
          <frame_name>imu_link</frame_name>
          <ros>
            <argument>~/out:=imu</argument>
          </ros>
        </plugin>
        <pose>-0.1 0 0.05 3.14159 -1.24159 3.14159</pose>
      </sensor>
      <gravity>1</gravity>
      <velocity_decay/>
      <sensor name='block_laser_sensor' type='ray'>
        <visualize>1</visualize>
        <ray>
          <scan>
            <horizontal>
              <samples>200</samples>
              <resolution>1</resolution>
              <min_angle>-0.9</min_angle>
              <max_angle>0.9</max_angle>
            </horizontal>
            <vertical>
              <samples>4</samples>
              <resolution>1</resolution>
              <min_angle>0</min_angle>
              <max_angle>0.05</max_angle>
            </vertical>
          </scan>
          <range>
            <min>0.1</min>
            <max>10</max>
            <resolution>0.01</resolution>
          </range>
        </ray>
        <update_rate>30</update_rate>
        <plugin name='gazebo_ros_block_laser_controller' filename='libgazebo_ros_ray_sensor.so'>
          <ros>
            <argument>~/out:=points2</argument>
          </ros>
          <output_type>sensor_msgs/PointCloud2</output_type>
          <topicName>points2</topicName>
          <frameName>four_layer</frameName>
          <min_intensity>100.0</min_intensity>
        </plugin>
        <pose>1.05 0 0.1 0 -0 0</pose>
      </sensor>
      <self_collide>0</self_collide>
      <enable_wind>0</enable_wind>
      <kinematic>0</kinematic>
      <plugin filename='libgazebo_ros_p3d.so' name='gps'>
        <ros>
          <argument>~/out:=gps</argument>
        </ros>
        <frame_name>map</frame_name>
        <body_name>base_link</body_name>
        <output_type>nav_msgs/Odometry</output_type>
        <update_rate>100.0</update_rate>
        <gaussian_noise>0.0</gaussian_noise>
      </plugin>
      <pose>0 0 0 0 -0 0</pose>
      <visual name='base_link_fixed_joint_lump__visual_0_visual'>
        <pose>-0.08 0 -0.2 0 -0 1.5708</pose>
        <geometry>
          <mesh>
            <scale>0.98 0.85 0.9</scale>
            <uri>file:////home/robsic/golfinho/install/golfinho_model/share/golfinho_model/meshes/base_link.dae</uri>
          </mesh>
        </geometry>
        <material>
          <shader type='pixel'/>
        </material>
        <transparency>0</transparency>
        <cast_shadows>1</cast_shadows>
      </visual>
      <visual name='base_link_fixed_joint_lump__visual_visual_1'>
        <pose>0.4 0 1.4 0 -0 0</pose>
        <geometry>
          <box>
            <size>0.01 0.01 0.01</size>
          </box>
        </geometry>
        <material>
          <shader type='pixel'/>
        </material>
        <transparency>0</transparency>
        <cast_shadows>1</cast_shadows>
      </visual>
      <visual name='base_link_fixed_joint_lump__visual_link_r_visual_2'>
        <pose>1 0 0.03 0 -0 0</pose>
        <geometry>
          <mesh>
            <scale>0.05 0.05 0.05</scale>
            <uri>file:////home/robsic/golfinho/install/golfinho_model/share/golfinho_model/meshes/sick_4camadas.dae</uri>
          </mesh>
        </geometry>
        <material>
          <shader type='pixel'/>
        </material>
        <transparency>0</transparency>
        <cast_shadows>1</cast_shadows>
      </visual>
      <visual name='base_link_fixed_joint_lump__visual_link_l_visual_3'>
        <pose>0.68 0.55 0.59 0 -0 0.7854</pose>
        <geometry>
          <mesh>
            <scale>0.0005 0.0005 0.0005</scale>
            <uri>file:////home/robsic/golfinho/install/golfinho_model/share/golfinho_model/meshes/sick_270.dae</uri>
          </mesh>
        </geometry>
        <material>
          <shader type='pixel'/>
        </material>
        <transparency>0</transparency>
        <cast_shadows>1</cast_shadows>
      </visual>
      <visual name='base_link_fixed_joint_lump__visual_link_r_visual_4'>
        <pose>0.68 -0.55 0.59 0 0 -0.7854</pose>
        <geometry>
          <mesh>
            <scale>0.0005 0.0005 0.0005</scale>
            <uri>/home/robsic/golfinho/install/golfinho_model/share/golfinho_model/meshes/sick_270.dae</uri>
          </mesh>
        </geometry>
        <material>
          <shader type='pixel'/>
        </material>
        <transparency>0</transparency>
        <cast_shadows>1</cast_shadows>
      </visual>
      <collision name='base_link_fixed_joint_lump__collision_collision'>
        <laser_retro>0</laser_retro>
        <max_contacts>10</max_contacts>
        <pose>0 0 0 0 -0 0</pose>
        <geometry>
          <box>
            <size>1 0.05 0.01</size>
          </box>
        </geometry>
        <surface>
          <friction>
            <ode>
              <mu>1</mu>
              <mu2>1</mu2>
              <fdir1>0 0 0</fdir1>
              <slip1>0</slip1>
              <slip2>0</slip2>
            </ode>
            <torsional>
              <coefficient>1</coefficient>
              <patch_radius>0</patch_radius>
              <surface_radius>0</surface_radius>
              <use_patch_radius>1</use_patch_radius>
              <ode>
                <slip>0</slip>
              </ode>
            </torsional>
          </friction>
          <bounce>
            <restitution_coefficient>0</restitution_coefficient>
            <threshold>1e+06</threshold>
          </bounce>
          <contact>
            <collide_without_contact>0</collide_without_contact>
            <collide_without_contact_bitmask>1</collide_without_contact_bitmask>
            <collide_bitmask>1</collide_bitmask>
            <ode>
              <soft_cfm>0</soft_cfm>
              <soft_erp>0.2</soft_erp>
              <kp>1e+13</kp>
              <kd>1</kd>
              <max_vel>0.01</max_vel>
              <min_depth>0</min_depth>
            </ode>
            <bullet>
              <split_impulse>1</split_impulse>
              <split_impulse_penetration_threshold>-0.01</split_impulse_penetration_threshold>
              <soft_cfm>0</soft_cfm>
              <soft_erp>0.2</soft_erp>
              <kp>1e+13</kp>
              <kd>1</kd>
            </bullet>
          </contact>
        </surface>
      </collision>
      <collision name='base_link_fixed_joint_lump__collision_collision_1'>
        <laser_retro>0</laser_retro>
        <max_contacts>10</max_contacts>
        <pose>0.4 0 1.4 0 -0 0</pose>
        <geometry>
          <box>
            <size>0.01 0.01 0.01</size>
          </box>
        </geometry>
        <surface>
          <friction>
            <ode>
              <mu>1</mu>
              <mu2>1</mu2>
              <fdir1>0 0 0</fdir1>
              <slip1>0</slip1>
              <slip2>0</slip2>
            </ode>
            <torsional>
              <coefficient>1</coefficient>
              <patch_radius>0</patch_radius>
              <surface_radius>0</surface_radius>
              <use_patch_radius>1</use_patch_radius>
              <ode>
                <slip>0</slip>
              </ode>
            </torsional>
          </friction>
          <bounce>
            <restitution_coefficient>0</restitution_coefficient>
            <threshold>1e+06</threshold>
          </bounce>
          <contact>
            <collide_without_contact>0</collide_without_contact>
            <collide_without_contact_bitmask>1</collide_without_contact_bitmask>
            <collide_bitmask>1</collide_bitmask>
            <ode>
              <soft_cfm>0</soft_cfm>
              <soft_erp>0.2</soft_erp>
              <kp>1e+13</kp>
              <kd>1</kd>
              <max_vel>0.01</max_vel>
              <min_depth>0</min_depth>
            </ode>
            <bullet>
              <split_impulse>1</split_impulse>
              <split_impulse_penetration_threshold>-0.01</split_impulse_penetration_threshold>
              <soft_cfm>0</soft_cfm>
              <soft_erp>0.2</soft_erp>
              <kp>1e+13</kp>
              <kd>1</kd>
            </bullet>
          </contact>
        </surface>
      </collision>
      <collision name='base_link_fixed_joint_lump__collision_link_l_collision_2'>
        <laser_retro>0</laser_retro>
        <max_contacts>10</max_contacts>
        <pose>0.68 0.55 0.71 0 -0 0</pose>
        <geometry>
          <box>
            <size>0.153353 0.126857 0.054761</size>
          </box>
        </geometry>
        <surface>
          <friction>
            <ode>
              <mu>1</mu>
              <mu2>1</mu2>
              <fdir1>0 0 0</fdir1>
              <slip1>0</slip1>
              <slip2>0</slip2>
            </ode>
            <torsional>
              <coefficient>1</coefficient>
              <patch_radius>0</patch_radius>
              <surface_radius>0</surface_radius>
              <use_patch_radius>1</use_patch_radius>
              <ode>
                <slip>0</slip>
              </ode>
            </torsional>
          </friction>
          <bounce>
            <restitution_coefficient>0</restitution_coefficient>
            <threshold>1e+06</threshold>
          </bounce>
          <contact>
            <collide_without_contact>0</collide_without_contact>
            <collide_without_contact_bitmask>1</collide_without_contact_bitmask>
            <collide_bitmask>1</collide_bitmask>
            <ode>
              <soft_cfm>0</soft_cfm>
              <soft_erp>0.2</soft_erp>
              <kp>1e+13</kp>
              <kd>1</kd>
              <max_vel>0.01</max_vel>
              <min_depth>0</min_depth>
            </ode>
            <bullet>
              <split_impulse>1</split_impulse>
              <split_impulse_penetration_threshold>-0.01</split_impulse_penetration_threshold>
              <soft_cfm>0</soft_cfm>
              <soft_erp>0.2</soft_erp>
              <kp>1e+13</kp>
              <kd>1</kd>
            </bullet>
          </contact>
        </surface>
      </collision>
      <collision name='base_link_fixed_joint_lump__collision_link_r_collision_3'>
        <laser_retro>0</laser_retro>
        <max_contacts>10</max_contacts>
        <pose>0.68 -0.55 0.71 0 -0 0</pose>
        <geometry>
          <box>
            <size>0.153353 0.126857 0.054761</size>
          </box>
        </geometry>
        <surface>
          <friction>
            <ode>
              <mu>1</mu>
              <mu2>1</mu2>
              <fdir1>0 0 0</fdir1>
              <slip1>0</slip1>
              <slip2>0</slip2>
            </ode>
            <torsional>
              <coefficient>1</coefficient>
              <patch_radius>0</patch_radius>
              <surface_radius>0</surface_radius>
              <use_patch_radius>1</use_patch_radius>
              <ode>
                <slip>0</slip>
              </ode>
            </torsional>
          </friction>
          <bounce>
            <restitution_coefficient>0</restitution_coefficient>
            <threshold>1e+06</threshold>
          </bounce>
          <contact>
            <collide_without_contact>0</collide_without_contact>
            <collide_without_contact_bitmask>1</collide_without_contact_bitmask>
            <collide_bitmask>1</collide_bitmask>
            <ode>
              <soft_cfm>0</soft_cfm>
              <soft_erp>0.2</soft_erp>
              <kp>1e+13</kp>
              <kd>1</kd>
              <max_vel>0.01</max_vel>
              <min_depth>0</min_depth>
            </ode>
            <bullet>
              <split_impulse>1</split_impulse>
              <split_impulse_penetration_threshold>-0.01</split_impulse_penetration_threshold>
              <soft_cfm>0</soft_cfm>
              <soft_erp>0.2</soft_erp>
              <kp>1e+13</kp>
              <kd>1</kd>
            </bullet>
          </contact>
        </surface>
      </collision>
    </link>
    <link name='back_left_wheel'>
      <pose>-0.835 0.485 0 -1.5708 -0 -0</pose>
      <inertial>
        <pose>0 0 0 0 -0 0</pose>
        <mass>37.3751</mass>
        <inertia>
          <ixx>0.597613</ixx>
          <ixy>0</ixy>
          <ixz>0</ixz>
          <iyy>0.597613</iyy>
          <iyz>0</iyz>
          <izz>0.946058</izz>
        </inertia>
      </inertial>
      <gravity>1</gravity>
      <velocity_decay/>
      <self_collide>0</self_collide>
      <enable_wind>0</enable_wind>
      <kinematic>0</kinematic>
      <visual name='back_left_wheel_visual_0_visual'>
        <pose>0 0.38 0 1.5708 -0 0</pose>
        <geometry>
          <mesh>
            <scale>0.13 0.08 0.13</scale>
            <uri>file:////home/robsic/golfinho/install/golfinho_model/share/golfinho_model/meshes/wheel_.dae</uri>
          </mesh>
        </geometry>
        <material>
          <shader type='pixel'/>
        </material>
        <transparency>0</transparency>
        <cast_shadows>1</cast_shadows>
      </visual>
      <collision name='back_left_wheel_collision_collision'>
        <laser_retro>0</laser_retro>
        <max_contacts>10</max_contacts>
        <pose>0 0 0 0 -0 0</pose>
        <geometry>
          <cylinder>
            <radius>0.225</radius>
            <length>0.6</length>
          </cylinder>
        </geometry>
        <surface>
          <friction>
            <ode>
              <mu>1</mu>
              <mu2>1</mu2>
              <fdir1>0 0 0</fdir1>
              <slip1>0</slip1>
              <slip2>0</slip2>
            </ode>
            <torsional>
              <coefficient>1</coefficient>
              <patch_radius>0</patch_radius>
              <surface_radius>0</surface_radius>
              <use_patch_radius>1</use_patch_radius>
              <ode>
                <slip>0</slip>
              </ode>
            </torsional>
          </friction>
          <bounce>
            <restitution_coefficient>0</restitution_coefficient>
            <threshold>1e+06</threshold>
          </bounce>
          <contact>
            <collide_without_contact>0</collide_without_contact>
            <collide_without_contact_bitmask>1</collide_without_contact_bitmask>
            <collide_bitmask>1</collide_bitmask>
            <ode>
              <soft_cfm>0</soft_cfm>
              <soft_erp>0.2</soft_erp>
              <kp>1e+07</kp>
              <kd>1</kd>
              <max_vel>0.01</max_vel>
              <min_depth>0</min_depth>
            </ode>
            <bullet>
              <split_impulse>1</split_impulse>
              <split_impulse_penetration_threshold>-0.01</split_impulse_penetration_threshold>
              <soft_cfm>0</soft_cfm>
              <soft_erp>0.2</soft_erp>
              <kp>1e+07</kp>
              <kd>1</kd>
            </bullet>
          </contact>
        </surface>
      </collision>
    </link>
    <link name='back_right_wheel'>
      <pose>-0.835 -0.485 0 -1.5708 -0 -0</pose>
      <inertial>
        <pose>0 0 0 0 -0 0</pose>
        <mass>37.3751</mass>
        <inertia>
          <ixx>0.597613</ixx>
          <ixy>0</ixy>
          <ixz>0</ixz>
          <iyy>0.597613</iyy>
          <iyz>0</iyz>
          <izz>0.946058</izz>
        </inertia>
      </inertial>
      <gravity>1</gravity>
      <velocity_decay/>
      <self_collide>0</self_collide>
      <enable_wind>0</enable_wind>
      <kinematic>0</kinematic>
      <visual name='back_right_wheel_fixed_joint_lump__back_left_wheel_visual_0_visual'>
        <pose>0 -0.38 0 -1.5708 0 0</pose>
        <geometry>
          <mesh>
            <scale>0.13 0.08 0.13</scale>
            <uri>file:////home/robsic/golfinho/install/golfinho_model/share/golfinho_model/meshes/wheel_.dae</uri>
          </mesh>
        </geometry>
        <material>
          <shader type='pixel'/>
        </material>
        <transparency>0</transparency>
        <cast_shadows>1</cast_shadows>
      </visual>
      <collision name='back_right_wheel_collision_collision'>
        <laser_retro>0</laser_retro>
        <max_contacts>10</max_contacts>
        <pose>0 0 0 0 -0 0</pose>
        <geometry>
          <cylinder>
            <radius>0.225</radius>
            <length>0.6</length>
          </cylinder>
        </geometry>
        <surface>
          <friction>
            <ode>
              <mu>1</mu>
              <mu2>1</mu2>
              <fdir1>0 0 0</fdir1>
              <slip1>0</slip1>
              <slip2>0</slip2>
            </ode>
            <torsional>
              <coefficient>1</coefficient>
              <patch_radius>0</patch_radius>
              <surface_radius>0</surface_radius>
              <use_patch_radius>1</use_patch_radius>
              <ode>
                <slip>0</slip>
              </ode>
            </torsional>
          </friction>
          <bounce>
            <restitution_coefficient>0</restitution_coefficient>
            <threshold>1e+06</threshold>
          </bounce>
          <contact>
            <collide_without_contact>0</collide_without_contact>
            <collide_without_contact_bitmask>1</collide_without_contact_bitmask>
            <collide_bitmask>1</collide_bitmask>
            <ode>
              <soft_cfm>0</soft_cfm>
              <soft_erp>0.2</soft_erp>
              <kp>1e+07</kp>
              <kd>1</kd>
              <max_vel>0.01</max_vel>
              <min_depth>0</min_depth>
            </ode>
            <bullet>
              <split_impulse>1</split_impulse>
              <split_impulse_penetration_threshold>-0.01</split_impulse_penetration_threshold>
              <soft_cfm>0</soft_cfm>
              <soft_erp>0.2</soft_erp>
              <kp>1e+07</kp>
              <kd>1</kd>
            </bullet>
          </contact>
        </surface>
      </collision>
    </link>
    <link name='front_left_mount'>
      <pose>0.835 0.45 0 -1.5708 -0 -0</pose>
      <inertial>
        <pose>0 0 0 0 -0 0</pose>
        <mass>0.00064182</mass>
        <inertia>
          <ixx>2.11e-06</ixx>
          <ixy>0</ixy>
          <ixz>0</ixz>
          <iyy>2.11e-06</iyy>
          <iyz>0</iyz>
          <izz>2.7e-07</izz>
        </inertia>
      </inertial>
      <gravity>1</gravity>
      <velocity_decay/>
      <self_collide>0</self_collide>
      <enable_wind>0</enable_wind>
      <kinematic>0</kinematic>
      <visual name='front_left_mount_visual_visual'>
        <pose>0 0 0 1.5708 -0 0</pose>
        <geometry>
          <cylinder>
            <length>0.0001</length>
            <radius>0.0001</radius>
          </cylinder>
        </geometry>
        <material>
          <shader type='pixel'/>
        </material>
        <transparency>0</transparency>
        <cast_shadows>1</cast_shadows>
      </visual>
      <collision name='front_left_mount_collision_collision'>
        <laser_retro>0</laser_retro>
        <max_contacts>10</max_contacts>
        <pose>0 0 0 0 -0 0</pose>
        <geometry>
          <cylinder>
            <radius>0.115</radius>
            <length>0.072407</length>
          </cylinder>
        </geometry>
        <surface>
          <friction>
            <ode>
              <mu>1</mu>
              <mu2>1</mu2>
              <fdir1>0 0 0</fdir1>
              <slip1>0</slip1>
              <slip2>0</slip2>
            </ode>
            <torsional>
              <coefficient>1</coefficient>
              <patch_radius>0</patch_radius>
              <surface_radius>0</surface_radius>
              <use_patch_radius>1</use_patch_radius>
              <ode>
                <slip>0</slip>
              </ode>
            </torsional>
          </friction>
          <bounce>
            <restitution_coefficient>0</restitution_coefficient>
            <threshold>1e+06</threshold>
          </bounce>
          <contact>
            <collide_without_contact>0</collide_without_contact>
            <collide_without_contact_bitmask>1</collide_without_contact_bitmask>
            <collide_bitmask>1</collide_bitmask>
            <ode>
              <soft_cfm>0</soft_cfm>
              <soft_erp>0.2</soft_erp>
              <kp>1e+07</kp>
              <kd>1</kd>
              <max_vel>0.01</max_vel>
              <min_depth>0</min_depth>
            </ode>
            <bullet>
              <split_impulse>1</split_impulse>
              <split_impulse_penetration_threshold>-0.01</split_impulse_penetration_threshold>
              <soft_cfm>0</soft_cfm>
              <soft_erp>0.2</soft_erp>
              <kp>1e+07</kp>
              <kd>1</kd>
            </bullet>
          </contact>
        </surface>
      </collision>
    </link>
    <link name='front_left_wheel'>
      <pose>0.835 0.45 0 -1.5708 -0 -0</pose>
      <inertial>
        <pose>0 0 0 0 -0 0</pose>
        <mass>37.3751</mass>
        <inertia>
          <ixx>0.597613</ixx>
          <ixy>0</ixy>
          <ixz>0</ixz>
          <iyy>0.597613</iyy>
          <iyz>0</iyz>
          <izz>0.946058</izz>
        </inertia>
      </inertial>
      <gravity>1</gravity>
      <velocity_decay/>
      <self_collide>0</self_collide>
      <enable_wind>0</enable_wind>
      <kinematic>0</kinematic>
      <visual name='front_left_wheel_visual_0_visual'>
        <pose>0 -0.38 0 -1.5708 0 0</pose>
        <geometry>
          <mesh>
            <scale>0.13 0.08 0.13</scale>
            <uri>file:////home/robsic/golfinho/install/golfinho_model/share/golfinho_model/meshes/wheel_.dae</uri>
          </mesh>
        </geometry>
        <material>
          <shader type='pixel'/>
        </material>
        <transparency>0</transparency>
        <cast_shadows>1</cast_shadows>
      </visual>
      <collision name='front_left_wheel_collision_collision'>
        <laser_retro>0</laser_retro>
        <max_contacts>10</max_contacts>
        <pose>0 0 0 0 -0 0</pose>
        <geometry>
          <cylinder>
            <radius>0.225</radius>
            <length>0.6</length>
          </cylinder>
        </geometry>
        <surface>
          <friction>
            <ode>
              <mu>1</mu>
              <mu2>1</mu2>
              <fdir1>0 0 0</fdir1>
              <slip1>0</slip1>
              <slip2>0</slip2>
            </ode>
            <torsional>
              <coefficient>1</coefficient>
              <patch_radius>0</patch_radius>
              <surface_radius>0</surface_radius>
              <use_patch_radius>1</use_patch_radius>
              <ode>
                <slip>0</slip>
              </ode>
            </torsional>
          </friction>
          <bounce>
            <restitution_coefficient>0</restitution_coefficient>
            <threshold>1e+06</threshold>
          </bounce>
          <contact>
            <collide_without_contact>0</collide_without_contact>
            <collide_without_contact_bitmask>1</collide_without_contact_bitmask>
            <collide_bitmask>1</collide_bitmask>
            <ode>
              <soft_cfm>0</soft_cfm>
              <soft_erp>0.2</soft_erp>
              <kp>1e+07</kp>
              <kd>1</kd>
              <max_vel>0.01</max_vel>
              <min_depth>0</min_depth>
            </ode>
            <bullet>
              <split_impulse>1</split_impulse>
              <split_impulse_penetration_threshold>-0.01</split_impulse_penetration_threshold>
              <soft_cfm>0</soft_cfm>
              <soft_erp>0.2</soft_erp>
              <kp>1e+07</kp>
              <kd>1</kd>
            </bullet>
          </contact>
        </surface>
      </collision>
    </link>
    <link name='front_right_mount'>
      <pose>0.835 -0.45 -0 -1.5708 -0 -0</pose>
      <inertial>
        <pose>0 0 0 0 -0 0</pose>
        <mass>0.00064182</mass>
        <inertia>
          <ixx>2.11e-06</ixx>
          <ixy>0</ixy>
          <ixz>0</ixz>
          <iyy>2.11e-06</iyy>
          <iyz>0</iyz>
          <izz>2.7e-07</izz>
        </inertia>
      </inertial>
      <gravity>1</gravity>
      <velocity_decay/>
      <self_collide>0</self_collide>
      <enable_wind>0</enable_wind>
      <kinematic>0</kinematic>
      <visual name='front_right_mount_visual_visual'>
        <pose>0 0 0 1.5708 -0 0</pose>
        <geometry>
          <cylinder>
            <length>0.0001</length>
            <radius>0.0001</radius>
          </cylinder>
        </geometry>
        <material>
          <shader type='pixel'/>
        </material>
        <transparency>0</transparency>
        <cast_shadows>1</cast_shadows>
      </visual>
      <collision name='front_right_mount_collision_collision'>
        <laser_retro>0</laser_retro>
        <max_contacts>10</max_contacts>
        <pose>0 0 0 0 -0 0</pose>
        <geometry>
          <cylinder>
            <radius>0.115</radius>
            <length>0.072407</length>
          </cylinder>
        </geometry>
        <surface>
          <friction>
            <ode>
              <mu>1</mu>
              <mu2>1</mu2>
              <fdir1>0 0 0</fdir1>
              <slip1>0</slip1>
              <slip2>0</slip2>
            </ode>
            <torsional>
              <coefficient>1</coefficient>
              <patch_radius>0</patch_radius>
              <surface_radius>0</surface_radius>
              <use_patch_radius>1</use_patch_radius>
              <ode>
                <slip>0</slip>
              </ode>
            </torsional>
          </friction>
          <bounce>
            <restitution_coefficient>0</restitution_coefficient>
            <threshold>1e+06</threshold>
          </bounce>
          <contact>
            <collide_without_contact>0</collide_without_contact>
            <collide_without_contact_bitmask>1</collide_without_contact_bitmask>
            <collide_bitmask>1</collide_bitmask>
            <ode>
              <soft_cfm>0</soft_cfm>
              <soft_erp>0.2</soft_erp>
              <kp>1e+07</kp>
              <kd>1</kd>
              <max_vel>0.01</max_vel>
              <min_depth>0</min_depth>
            </ode>
            <bullet>
              <split_impulse>1</split_impulse>
              <split_impulse_penetration_threshold>-0.01</split_impulse_penetration_threshold>
              <soft_cfm>0</soft_cfm>
              <soft_erp>0.2</soft_erp>
              <kp>1e+07</kp>
              <kd>1</kd>
            </bullet>
          </contact>
        </surface>
      </collision>
    </link>
    <link name='front_right_wheel'>
      <pose>0.835 -0.45 -0 -1.5708 -0 -0</pose>
      <inertial>
        <pose>0 0 0 0 -0 0</pose>
        <mass>37.3751</mass>
        <inertia>
          <ixx>0.597613</ixx>
          <ixy>0</ixy>
          <ixz>0</ixz>
          <iyy>0.597613</iyy>
          <iyz>0</iyz>
          <izz>0.946058</izz>
        </inertia>
      </inertial>
      <gravity>1</gravity>
      <velocity_decay/>
      <self_collide>0</self_collide>
      <enable_wind>0</enable_wind>
      <kinematic>0</kinematic>
      <visual name='front_right_wheel_visual_0_visual'>
        <pose>0 0.38 0 1.5708 -0 0</pose>
        <geometry>
          <mesh>
            <scale>0.13 0.08 0.13</scale>
            <uri>file:////home/robsic/golfinho/install/golfinho_model/share/golfinho_model/meshes/wheel_.dae</uri>
          </mesh>
        </geometry>
        <material>
          <shader type='pixel'/>
        </material>
        <transparency>0</transparency>
        <cast_shadows>1</cast_shadows>
      </visual>
      <collision name='front_right_wheel_collision_collision'>
        <laser_retro>0</laser_retro>
        <max_contacts>10</max_contacts>
        <pose>0 0 0 0 -0 0</pose>
        <geometry>
          <cylinder>
            <radius>0.225</radius>
            <length>0.6</length>
          </cylinder>
        </geometry>
        <surface>
          <friction>
            <ode>
              <mu>1</mu>
              <mu2>1</mu2>
              <fdir1>0 0 0</fdir1>
              <slip1>0</slip1>
              <slip2>0</slip2>
            </ode>
            <torsional>
              <coefficient>1</coefficient>
              <patch_radius>0</patch_radius>
              <surface_radius>0</surface_radius>
              <use_patch_radius>1</use_patch_radius>
              <ode>
                <slip>0</slip>
              </ode>
            </torsional>
          </friction>
          <bounce>
            <restitution_coefficient>0</restitution_coefficient>
            <threshold>1e+06</threshold>
          </bounce>
          <contact>
            <collide_without_contact>0</collide_without_contact>
            <collide_without_contact_bitmask>1</collide_without_contact_bitmask>
            <collide_bitmask>1</collide_bitmask>
            <ode>
              <soft_cfm>0</soft_cfm>
              <soft_erp>0.2</soft_erp>
              <kp>1e+07</kp>
              <kd>1</kd>
              <max_vel>0.01</max_vel>
              <min_depth>0</min_depth>
            </ode>
            <bullet>
              <split_impulse>1</split_impulse>
              <split_impulse_penetration_threshold>-0.01</split_impulse_penetration_threshold>
              <soft_cfm>0</soft_cfm>
              <soft_erp>0.2</soft_erp>
              <kp>1e+07</kp>
              <kd>1</kd>
            </bullet>
          </contact>
        </surface>
      </collision>
    </link>
    <link name='steering'>
      <pose>0.194763 0.27693 0.818981 1e-06 -0.872602 -6.8e-05</pose>
      <inertial>
        <pose>0 0 0 0 -0 0</pose>
        <mass>0.00016233</mass>
        <inertia>
          <ixx>6e-08</ixx>
          <ixy>0</ixy>
          <ixz>0</ixz>
          <iyy>6e-08</iyy>
          <iyz>0</iyz>
          <izz>8e-08</izz>
        </inertia>
      </inertial>
      <self_collide>0</self_collide>
      <enable_wind>0</enable_wind>
      <kinematic>0</kinematic>
      <visual name='steering_fixed_joint_lump__visual_visual'>
        <pose>0 0 -0.07 1.4108 -0 0</pose>
        <geometry>
          <mesh>
            <scale>0.1 0.1 0.1</scale>
            <uri>file:////home/robsic/golfinho/install/golfinho_model/share/golfinho_model/meshes/steering.dae</uri>
          </mesh>
        </geometry>
        <material>
          <shader type='pixel'/>
        </material>
        <transparency>0</transparency>
        <cast_shadows>1</cast_shadows>
      </visual>
      <collision name='steering_fixed_joint_lump__collision_collision'>
        <laser_retro>0</laser_retro>
        <max_contacts>10</max_contacts>
        <pose>-0.012 -0.01 -0.04 0 -0 0</pose>
        <geometry>
          <cylinder>
            <radius>0.0001</radius>
            <length>0.0001</length>
          </cylinder>
        </geometry>
        <surface>
          <friction>
            <ode>
              <mu>1</mu>
              <mu2>1</mu2>
              <fdir1>0 0 0</fdir1>
              <slip1>0</slip1>
              <slip2>0</slip2>
            </ode>
            <torsional>
              <coefficient>1</coefficient>
              <patch_radius>0</patch_radius>
              <surface_radius>0</surface_radius>
              <use_patch_radius>1</use_patch_radius>
              <ode>
                <slip>0</slip>
              </ode>
            </torsional>
          </friction>
          <bounce>
            <restitution_coefficient>0</restitution_coefficient>
            <threshold>1e+06</threshold>
          </bounce>
          <contact>
            <collide_without_contact>0</collide_without_contact>
            <collide_without_contact_bitmask>1</collide_without_contact_bitmask>
            <collide_bitmask>1</collide_bitmask>
            <ode>
              <soft_cfm>0</soft_cfm>
              <soft_erp>0.2</soft_erp>
              <kp>1e+13</kp>
              <kd>1</kd>
              <max_vel>0.01</max_vel>
              <min_depth>0</min_depth>
            </ode>
            <bullet>
              <split_impulse>1</split_impulse>
              <split_impulse_penetration_threshold>-0.01</split_impulse_penetration_threshold>
              <soft_cfm>0</soft_cfm>
              <soft_erp>0.2</soft_erp>
              <kp>1e+13</kp>
              <kd>1</kd>
            </bullet>
          </contact>
        </surface>
      </collision>
    </link>
    <joint name='back_left_wheel_joint' type='revolute'>
      <parent>base_link</parent>
      <child>back_left_wheel</child>
      <pose>0 -0 0 0 -0 0</pose>
      <axis>
        <xyz>0 0 1</xyz>
        <limit>
          <lower>-1e+16</lower>
          <upper>1e+16</upper>
          <effort>-1</effort>
          <velocity>-1</velocity>
        </limit>
        <dynamics>
          <spring_reference>0</spring_reference>
          <spring_stiffness>0</spring_stiffness>
          <damping>0</damping>
          <friction>0</friction>
        </dynamics>
      </axis>
      <physics>
        <ode>
          <limit>
            <cfm>0</cfm>
            <erp>0.2</erp>
          </limit>
          <suspension>
            <cfm>0</cfm>
            <erp>0.2</erp>
          </suspension>
        </ode>
      </physics>
    </joint>
    <joint name='back_right_wheel_joint' type='revolute'>
      <parent>base_link</parent>
      <child>back_right_wheel</child>
      <pose>0 0 -0 0 -0 0</pose>
      <axis>
        <xyz>0 0 1</xyz>
        <limit>
          <lower>-1e+16</lower>
          <upper>1e+16</upper>
          <effort>-1</effort>
          <velocity>-1</velocity>
        </limit>
        <dynamics>
          <spring_reference>0</spring_reference>
          <spring_stiffness>0</spring_stiffness>
          <damping>0</damping>
          <friction>0</friction>
        </dynamics>
      </axis>
      <physics>
        <ode>
          <limit>
            <cfm>0</cfm>
            <erp>0.2</erp>
          </limit>
          <suspension>
            <cfm>0</cfm>
            <erp>0.2</erp>
          </suspension>
        </ode>
      </physics>
    </joint>
    <joint name='front_left_mount_joint' type='revolute'>
      <parent>base_link</parent>
      <child>front_left_mount</child>
      <pose>0 -0 0 0 -0 0</pose>
      <axis>
        <xyz>0 -1 0</xyz>
        <limit>
          <lower>-1e+16</lower>
          <upper>1e+16</upper>
          <effort>-1</effort>
          <velocity>-1</velocity>
        </limit>
        <dynamics>
          <spring_reference>0</spring_reference>
          <spring_stiffness>0</spring_stiffness>
          <damping>0</damping>
          <friction>0</friction>
        </dynamics>
      </axis>
      <physics>
        <ode>
          <limit>
            <cfm>0</cfm>
            <erp>0.2</erp>
          </limit>
          <suspension>
            <cfm>0</cfm>
            <erp>0.2</erp>
          </suspension>
        </ode>
      </physics>
    </joint>
    <joint name='front_left_wheel_joint' type='revolute'>
      <parent>front_left_mount</parent>
      <child>front_left_wheel</child>
      <pose>0 -0 0 0 -0 0</pose>
      <axis>
        <xyz>0 0 1</xyz>
        <limit>
          <lower>-1e+16</lower>
          <upper>1e+16</upper>
          <effort>-1</effort>
          <velocity>-1</velocity>
        </limit>
        <dynamics>
          <spring_reference>0</spring_reference>
          <spring_stiffness>0</spring_stiffness>
          <damping>0</damping>
          <friction>0</friction>
        </dynamics>
      </axis>
      <physics>
        <ode>
          <limit>
            <cfm>0</cfm>
            <erp>0.2</erp>
          </limit>
          <suspension>
            <cfm>0</cfm>
            <erp>0.2</erp>
          </suspension>
        </ode>
      </physics>
    </joint>
    <joint name='front_right_mount_joint' type='revolute'>
      <parent>base_link</parent>
      <child>front_right_mount</child>
      <pose>0 0 -0 0 -0 0</pose>
      <axis>
        <xyz>0 -1 0</xyz>
        <limit>
          <lower>-1e+16</lower>
          <upper>1e+16</upper>
          <effort>-1</effort>
          <velocity>-1</velocity>
        </limit>
        <dynamics>
          <spring_reference>0</spring_reference>
          <spring_stiffness>0</spring_stiffness>
          <damping>0</damping>
          <friction>0</friction>
        </dynamics>
      </axis>
      <physics>
        <ode>
          <limit>
            <cfm>0</cfm>
            <erp>0.2</erp>
          </limit>
          <suspension>
            <cfm>0</cfm>
            <erp>0.2</erp>
          </suspension>
        </ode>
      </physics>
    </joint>
    <joint name='front_right_wheel_joint' type='revolute'>
      <parent>front_right_mount</parent>
      <child>front_right_wheel</child>
      <pose>0 0 -0 0 -0 0</pose>
      <axis>
        <xyz>0 0 1</xyz>
        <limit>
          <lower>-1e+16</lower>
          <upper>1e+16</upper>
          <effort>-1</effort>
          <velocity>-1</velocity>
        </limit>
        <dynamics>
          <spring_reference>0</spring_reference>
          <spring_stiffness>0</spring_stiffness>
          <damping>0</damping>
          <friction>0</friction>
        </dynamics>
      </axis>
      <physics>
        <ode>
          <limit>
            <cfm>0</cfm>
            <erp>0.2</erp>
          </limit>
          <suspension>
            <cfm>0</cfm>
            <erp>0.2</erp>
          </suspension>
        </ode>
      </physics>
    </joint>
    <joint name='steering_joint' type='revolute'>
      <parent>base_link</parent>
      <child>steering</child>
      <pose>0 0 0 0 -0 0</pose>
      <axis>
        <xyz>0 0 -1</xyz>
        <limit>
          <lower>-1e+16</lower>
          <upper>1e+16</upper>
          <effort>-1</effort>
          <velocity>-1</velocity>
        </limit>
        <dynamics>
          <spring_reference>0</spring_reference>
          <spring_stiffness>0</spring_stiffness>
          <damping>0</damping>
          <friction>0</friction>
        </dynamics>
      </axis>
      <physics>
        <ode>
          <limit>
            <cfm>0</cfm>
            <erp>0.2</erp>
          </limit>
          <suspension>
            <cfm>0</cfm>
            <erp>0.2</erp>
          </suspension>
        </ode>
      </physics>
    </joint>
    <static>0</static>
    <allow_auto_disable>1</allow_auto_disable>
    <plugin name='ackermann_drive' filename='libgazebo_ros_ackermann_drive.so'>
      <update_rate>100.0</update_rate>
      <front_left_joint>front_left_wheel_joint</front_left_joint>
      <front_right_joint>front_right_wheel_joint</front_right_joint>
      <rear_left_joint>back_left_wheel_joint</rear_left_joint>
      <rear_right_joint>back_right_wheel_joint</rear_right_joint>
      <left_steering_joint>front_left_mount_joint</left_steering_joint>
      <right_steering_joint>front_right_mount_joint</right_steering_joint>
      <steering_wheel_joint>steering_joint</steering_wheel_joint>
      <max_steer>0.523</max_steer>
      <max_steering_angle>9.42</max_steering_angle>
      <max_speed>20</max_speed>
      <left_steering_pid_gain>6000 0 1</left_steering_pid_gain>
      <left_steering_i_range>0 0</left_steering_i_range>
      <right_steering_pid_gain>6000 0 1</right_steering_pid_gain>
      <right_steering_i_range>0 0</right_steering_i_range>
      <linear_velocity_pid_gain>1000 0 1</linear_velocity_pid_gain>
      <linear_velocity_i_range>0 0</linear_velocity_i_range>
      <publish_odom>1</publish_odom>
      <publish_odom_tf>1</publish_odom_tf>
      <publish_wheel_tf>1</publish_wheel_tf>
      <publish_distance>1</publish_distance>
      <odometry_frame>odom</odometry_frame>
      <robot_base_frame>base_link</robot_base_frame>
    </plugin>
    <plugin name='gazebo_ros_joint_pose_trajectory' filename='libgazebo_ros_joint_pose_trajectory.so'>
      <update_rate>50</update_rate>
    </plugin>
    <plugin name='laser_link_right' filename='libgazebo_ros_joint_pose_trajectory.so'>
      <ros/>
      <update_rate>30</update_rate>
    </plugin>
  </model>
</sdf>
