<?xml version="1.0"?>

<robot name="golfinho">
  
  
    <!-- ****************** ROBOT BASE FOOTPRINT ***************************  -->
  <!-- Define the center of the main robot chassis projected on the ground 	-->
  <link name="base_footprint"/> 

  <!-- The base footprint of the robot is located underneath the chassis -->
  <joint name="base_joint" type="fixed">
    <parent link="base_footprint"/>
    <child link="base_link" />
    <origin xyz="0.0 0.0 -0.05" rpy="0 0 0"/>
  </joint>


 <link name='base_link'>
   
      <inertial>
        <mass value="160"/>
        <origin rpy="0 0 0" xyz="0 0 0"/>
        <inertia ixx="10" ixy="0" ixz="0" iyy="10" iyz="0" izz="10"/>
      </inertial>
      
      <collision name='collision'>
        <geometry>
            <box size="1 0.05 0.01"/>
	      </geometry>
      </collision>

      <visual name='visual_0'>
       <origin rpy="0 -0 0" xyz="0.1 0 -0.2"/>
        <geometry>
          <mesh filename="file:///$(find golfinho_model)/meshes/golfinho/base.dae" scale="1.105 1 1"/>   
        </geometry>
      </visual>
</link>

  <!-- ***************** -->
  <!--      Whells       -->
  <!-- ***************** -->
  
  <!-- ***************** -->
  <!--       Links       -->
  <!-- ***************** -->
    
    <link name='front_left_wheel'>
      <inertial>
        <mass value="37.37513510"/>
        <origin rpy="0 0 0" xyz="0 0 0"/>
        <inertia ixx="0.59" ixy="0" ixz="0" iyy="0.59" iyz="0" izz="0.94"/>
     </inertial>

      <collision name='front_left_wheel_collision'>
        <geometry>
          <cylinder length="0.6" radius="0.225"/>
	     </geometry>
      </collision>

      <visual name='front_left_wheel_visual_0'>
       <origin rpy="-1.570800 0 0" xyz="0 0 0"/>
         <geometry>
             <mesh filename="file:///$(find golfinho_model)/meshes/golfinho/wheel.dae"  scale="1 1 1"/>
         </geometry>
      </visual>
    </link>
  
  
   <link name="front_left_mount">
     <inertial>
        <mass value="0.00064182"/>
        <origin rpy="0 0 0" xyz="0 0 0"/>
        <inertia ixx="2.11e-06" ixy="0" ixz="0" iyy="2.11e-06" iyz="0" izz="2.7e-07"/>
      </inertial> 

      <collision name='front_left_mount_collision'>
        <geometry>
           <cylinder length="0.072407" radius="0.115000"/>
	      </geometry>
      </collision>

    <visual name='front_left_mount_visual'>
        <geometry>
          <cylinder length="0.0001" radius="0.0001"/>
	 </geometry>
       <origin rpy="1.5708 0 0" xyz="0 0 0"/>
    </visual>
   </link>

  <link name='front_right_wheel'>  
      <inertial>
        <mass value="37.37513510"/>
        <origin rpy="0 0 0" xyz="0 0 0"/>
        <inertia ixx="0.59" ixy="0" ixz="0" iyy="0.59" iyz="0" izz="0.94"/>
      </inertial>
      
      <collision name='front_right_wheel_collision'>
        <geometry>
          <cylinder length="0.6" radius="0.225"/>
	      </geometry>
      </collision>

      <visual name='front_right_wheel_visual_0'>
          <origin rpy="1.570800 0 0" xyz="0 0 0"/>
         <geometry>
           <mesh filename="file:///$(find golfinho_model)/meshes/golfinho/wheel.dae"   scale="1 1 1"/>
         </geometry>
      </visual>
  </link>


  <link name="front_right_mount">
     <inertial>
        <mass value="0.00064182"/>
        <origin rpy="0 0 0" xyz="0 0 0"/>
        <inertia ixx="2.11e-06" ixy="0" ixz="0" iyy="2.11e-06" iyz="0" izz="2.7e-07"/>
      </inertial>

      <collision name='front_right_mount_collision'>
        <geometry>
          <cylinder length="0.072" radius="0.115"/>
	      </geometry>
      </collision>

    <visual name='front_right_mount_visual'>
        <geometry>
          <cylinder length="0.0001" radius="0.0001"/>
	      </geometry>
       <origin rpy="1.5708 0 0" xyz="0 0 0"/>
    </visual>
  </link>
 
 



<link name='back_left_wheel'>    
      <inertial>
        <mass value="37.37"/>
        <origin rpy="0 0 0" xyz="0 0 0"/>
        <inertia ixx="0.59" ixy="0" ixz="0" iyy="0.59" iyz="0" izz="0.94"/>
      </inertial>

      <collision name='back_left_wheel_collision'>
        <geometry>
          <cylinder length="0.6" radius="0.225"/>
	 </geometry>
      </collision>


      <visual name='back_left_wheel_visual_0'>
       <origin rpy="-1.570800 0 0" xyz="0 0 0"/>
         <geometry>
           <mesh filename="file:///$(find golfinho_model)/meshes/golfinho/wheel.dae"   scale="1 1 1"/>
         </geometry>
      </visual> 
</link>


<link name='back_right_wheel'> 
      <inertial>
        <mass value="37.37"/>
        <origin rpy="0 0 0" xyz="0 0 0"/>
        <inertia ixx="0.59" ixy="0" ixz="0" iyy="0.59" iyz="0" izz="0.94"/>
      </inertial>

      <collision name='back_right_wheel_collision'>
        <geometry>
          <cylinder length="0.6" radius="0.225"/>
	 </geometry>
      </collision>
 
       <visual name='back_left_wheel_visual_0'>
       <origin rpy="1.570800 0 0" xyz="0 0 0"/>
         <geometry>
           <mesh filename="file:///$(find golfinho_model)/meshes/golfinho/wheel.dae"   scale="1 1 1"/>
         </geometry>
      </visual>
 </link>



<link name='steering'>
      <inertial>
        <mass value="0.00016233"/>
        <origin rpy="0 0 0" xyz="0 0 0"/>
        <inertia ixx="6e-08" ixy="0" ixz="0" iyy="6e-08" iyz="0" izz="8e-08"/>
      </inertial>

      <collision name='collision'>
         <origin rpy="0 0 0" xyz="-0.012 -0.01 -0.04"/>
         <geometry>
          <cylinder length="0.0001" radius="0.0001"/>
	 </geometry>
      </collision>

     <visual name='visual'>
        <origin rpy="1.4108 0 0" xyz="0 0 -0.07"/>
        <geometry>
           <mesh filename="file:///$(find golfinho_model)/meshes/golfinho/steering.dae"  scale="0.01 0.01 0.01"/>
	</geometry>
     </visual>
</link>


  <!-- ***************** -->
  <!--      Joints       -->
  <!-- ***************** -->
    
    
<joint name="steering_joint" type="continuous">
    <parent link="base_link"/>
    <child link="steering"/>
    <axis xyz="0 0 -1"/>
    <origin rpy="1e-06 -0.872602 -6.8e-05" xyz=" 0.194763 0.27693 0.818981"/>
</joint>
    
    
<joint name="front_left_wheel_joint" type="continuous">
      <parent link="front_left_mount"/>
     <child link="front_left_wheel"/>
     <axis xyz="0 0 1"/>
     <origin rpy="0 0 0"  xyz="0.0 0.0 0.0"/>
</joint>
  
<joint name="front_left_mount_joint" type="continuous">
      <parent link="base_link"/>
     <child link="front_left_mount"/>
     <axis xyz="0 -1 0"/>
     <origin rpy="-1.5708 0 0" xyz="0.835 0.45 0.0"/>
</joint>
    
<joint name="front_right_wheel_joint" type="continuous">
      <parent link="front_right_mount"/>
      <child link="front_right_wheel"/>
      <axis xyz="0 0 1"/>
      <origin rpy="0 0 0"  xyz="0.0 0.0 0.0"/>
</joint>
 
 
<joint name="front_right_mount_joint" type="continuous">
      <parent link="base_link"/>
      <child link="front_right_mount"/>
      <axis xyz="0 -1 0"/>
      <origin rpy="-1.5708 0 0" xyz="0.835 -0.45 0.0"/>
</joint>


<joint name="back_left_wheel_joint" type="continuous">
    <parent link="base_link"/>
    <child link="back_left_wheel"/>
    <axis xyz="0 0 1"/>
    <origin rpy="-1.5708 0 0"  xyz="-0.835 0.485 0.0"/>
</joint>

 <joint name="back_right_wheel_joint" type="continuous">
     <parent link="base_link"/>
     <child link="back_right_wheel"/>
     <axis xyz="0 0 1"/>
     <origin rpy="-1.5708 0 0"  xyz="-0.835 -0.485 0.0"/>
</joint>
    
    
    
  <!-- ***************** -->
  <!--  Suport Lasers    -->
  <!-- ***************** -->
    
    
<link name='laser_link_4_layer_front'>
      <inertial>
        <mass value="0.00106532"/>
        <origin rpy="0 0 0" xyz="0 0 0"/>
        <inertia ixx="1.69e-06" ixy="0" ixz="0" iyy="2.35e-06" iyz="0" izz="3.52e-06"/>
      </inertial>
      
      <visual name='visual_link_front'>
        <origin rpy="0 0 0" xyz="0.0 0 0"/>
       <geometry>
         <mesh filename="file:///$(find golfinho_model)/meshes/golfinho/DAE_STL_sensores/sick_4camadas.dae"  scale="0.05 0.05 0.05"/>
        </geometry>
      </visual>
</link>

   
<link name='laser_link_4_layer_rear'>
      <inertial>
        <mass value="0.00106532"/>
        <origin rpy="0 0 0" xyz="0 0 0"/>
        <inertia ixx="1.69e-06" ixy="0" ixz="0" iyy="2.35e-06" iyz="0" izz="3.52e-06"/>
      </inertial>
      
      <visual name='visual_link_rear'>
        <origin rpy="0 0 3.1415" xyz="0 0 0"/>
       <geometry>
         <mesh filename="file:///$(find golfinho_model)/meshes/golfinho/DAE_STL_sensores/sick_4camadas.dae"  scale="0.05 0.05 0.05"/>
        </geometry>
      </visual>
</link>



<joint name="laser_suport" type="fixed">
    <parent link="base_link"/>
    <child link="laser_link_4_layer_front"/>
    <origin rpy="0 0 0" xyz="1.18 0 0.1"/>
</joint>


<joint name="laser_suport_4__layer_rear" type="fixed">
    <parent link="base_link"/>
    <child link="laser_link_4_layer_rear"/>
    <origin rpy="0 0 0" xyz="-1.16 0 0.3"/>
</joint>


<link name='laser_link_left'>
      <inertial>
        <mass value="0.00106532"/>
        <origin rpy="0 0 0" xyz="0 0 0"/>
        <inertia ixx="1.69e-06" ixy="0" ixz="0" iyy="2.35e-06" iyz="0" izz="3.52e-06"/>
      </inertial>
      
     <visual name='visual_link_l'>
       <origin rpy="0 -0 0.7854" xyz="0.0 0 -0.12"/>
       <geometry>
        <mesh filename="file:///$(find golfinho_model)/meshes/golfinho/DAE_STL_sensores/sick_270.dae"  scale="0.0005 0.0005 0.0005"/>
       </geometry>
     </visual>
      
      <collision name='collision_link_l'>
        <geometry>
         <box size="0.153353 0.126857 0.054761"/>
        </geometry>
      </collision>
</link>

<joint name="laser_suport_left" type="fixed">
     <parent link="base_link"/>
     <child link="laser_link_left"/>
     <origin xyz="0.68 0.55 0.71"/>
</joint>

<link name='laser_link_right'>
       <inertial>
        <mass value="0.00106532"/>
        <origin rpy="0 0 0" xyz="0 0 0"/>
        <inertia ixx="1.69e-06" ixy="0" ixz="0" iyy="2.35e-06" iyz="0" izz="3.52e-06"/>
      </inertial>
      
     <visual name='visual_link_r'>
       <origin rpy="0 -0 -0.7854" xyz="0 0 -0.12"/>
       <geometry>
        <mesh filename="file:///$(find golfinho_model)/meshes/golfinho/DAE_STL_sensores/sick_270.dae"   scale="0.0005 0.0005 0.0005"/>
       </geometry>
      </visual>
      
      <collision name='collision_link_r'>
        <geometry>
         <box size="0.153353 0.126857 0.054761"/>
        </geometry>
      </collision>
</link>

<joint name="laser_suport_right" type="fixed">
     <parent link="base_link"/>
     <child link="laser_link_right"/>
     <origin xyz="0.68 -0.55 0.71"/>
</joint>

<link name='camera_link'>
      <inertial>
        <mass value="0.00106532"/>
        <origin rpy="0 0 0" xyz="0 0 0"/>
        <inertia ixx="1.69e-06" ixy="0" ixz="0" iyy="2.35e-06" iyz="0" izz="3.52e-06"/>
      </inertial>      
   
     <visual name='visual'>
       <geometry>
        <box size="0.01 0.01 0.01"/>
        </geometry>
     </visual>
   
      <collision name='collision'>
        <geometry>
            <box size="0.01 0.01 0.01"/>
        </geometry>
      </collision>
</link>


<joint name="camera_front" type="fixed">
     <parent link="base_link"/>
     <child link="camera_link"/>
     <origin xyz="0.549294 0.023722 1.36833" rpy="0 0 0"/>
</joint>


 <link name="camera_link_optical">
        <inertial>
        <mass value="0.00106532"/>
        <origin rpy="0 0 0" xyz="0 0 0"/>
        <inertia ixx="1.69e-06" ixy="0" ixz="0" iyy="2.35e-06" iyz="0" izz="3.52e-06"/>
      </inertial>   
</link>


<joint name="camera_optical_joint" type="fixed">
    <origin xyz="0 0 0" rpy="0 0 0"/>
    <parent link="camera_link"/>
    <child link="camera_link_optical"/>
</joint>



  <!-- *********************** IMU SETUP *********************************  -->
  <!-- Each sensor must be attached to a link.                              --> 

  <link name="imu_link">
       <inertial>
        <mass value="0.1"/>
        <origin rpy="0 0 0" xyz="0 0 0"/>
        <inertia ixx="0.1" ixy="0" ixz="0" iyy="0.1" iyz="0" izz="0.1"/>
      </inertial>
</link>


<joint name="imu_link_joint" type="fixed">
    <parent link="base_link" />
    <child link="imu_link" />
    <origin xyz="0 0 0.01"  rpy="0 0.0 0" /> 
  </joint>


  <!-- *********************** GPS SETUP **********************************  -->
  <joint name="gps_joint" type="fixed">
    <parent link="base_link"/>
    <child link="gps_link"/>
    <origin xyz="0.10 0 50" rpy="0 0 0"/>
  </joint>

  <link name="gps_link"/>

</robot>
